Workbook

Sheet foxz

Sheet NHÔM_L1
A1: PHIẾU YÊU CẦU VẬT TƯ- PHỤ KIỆN
A2: Công trình :Ms Vân Anh - Thái Bình
A3: Mã Đơn Hàng :
A4: Chủng loại phụ kiện :
A5: Màu sắc : Xám Sần Metalic
A6: Địa chỉ giao hàng :
A8: TT | B8: Tên vật tư | C8: Mã vật tư | D8: Tỷ trọng | E8: Đơn vị | F8: Số lượng | G8: Khối lượng | H8: Ghi chú
A9: 1 | B9: Khung bao vách 55 | C9: C3209 | D9: 0.874 | E9: cây | F9: 9 | G9: =F9*6*D9 -> 47.196
A10: 2 | B10: Nẹp kính đơn vách | C10: C3295 | D10: 0.238 | E10: cây | F10: 9 | G10: =F10*6*D10 -> 12.852
A11: 3 | B11: Nẹp kính hộp vách | C11: C3236 | D11: 0.238 | E11: cây | F11: 3 | G11: =F11*6*D11 -> 4.284
A12: 4 | B12: Khung bao cửa sổ 55 | C12: C3318 | D12: 0.887 | E12: cây | F12: 10 | G12: =F12*6*D12 -> 53.22
A13: 5 | B13: Cánh cửa sổ mở quay phẳng mặt | C13: MT3202A | D13: 1.126 | E13: cây | F13: 10 | G13: =F13*6*D13 -> 67.56 | H13: STD mang về
A14: 6 | B14: Đố T chia khung | C14: C3313 | D14: 0.966 | E14: cây | F14: 1 | G14: =F14*6*D14 -> 5.796 | H14: Tận dụng DC
A15: 7 | B15: Khung bao cửa đi 55 | C15: C3328 | D15: 1.125 | E15: cây | F15: 7 | G15: =F15*6*D15 -> 47.25
A16: 8 | B16: Cánh cửa đi mở quay mới VRA55 | C16: VRA55-03 | D16: 1.515 | E16: cây | F16: 8 | G16: =F16*6*D16 -> 72.72 | H16: Loại mới có khoang
A17: 9 | B17: Đố động dùng chung | C17: C3323 | D17: 0.878 | E17: cây | F17: 1 | G17: =F17*6*D17 -> 5.268
A18: 10 | B18: Đố T chia vách | C18: C3203 | D18: 1.01 | E18: cây | F18: 1 | G18: =F18*6*D18 -> 6.06 | H18: Tận dụng DC
A19: 11 | B19: Ngưỡng nhôm | C19: C3319 | D19: 1.125 | E19: cây | F19: 1 | G19: =F19*6*D19 -> 6.75
B20: TỔNG CỘNG | F20: =SUM(F9:F19) -> 60 | G20: =SUM(G9:G19) -> 328.956

Sheet VTP_L1
A1: PHIẾU YÊU CẦU VẬT TƯ
B2: Ngày ..13..tháng ..12.. năm 2025
A3: Công trình : L1 Ms Vân Anh Thái Bình
A4: Mã Đơn Hàng :
A5: Chủng loại phụ kiện : Viralwindow
A6: Màu sắc :
A7: Địa chỉ giao hàng : Tại xưởng sản xuất : 36 Đường Miền Đông, Cự Khê Thanh Oai
A9: TT | B9: Mã VT | C9: Tên vật tư | D9: Đơn vị | E9: Số lượng | F9: NCC
A10: 1 | B10: KE 14*52 | C10: Ke tomahok khung vách | D10: cái | E10: 40
A11: 2 | B11: KE TC 11 | C11: Ke tăng cứng xingfa 11 | D11: cái | E11: =E10+E12+E13*3+E14+E15*3 -> 298
A12: 3 | B12: KE 32*43 | C12: Ke khung bao bao cửa đi | D12: cái | E12: 10
A13: 4 | B13: KE 36*43 | C13: Ke cánh cửa đi VRA | D13: cái | E13: 20
A14: 5 | B14: KE 14*43 | C14: Ke tomahok khung bao cửa sổ | D14: cái | E14: 44
A15: 6 | B15: KE 25*43 | C15: Ke tomahok cánh cửa sổ VRA | D15: cái | E15: =12*4 -> 48
A16: 7 | B16: GEDPM 2TP | C16: Gioang EDPM 2 thành phần | D16: cuộn | E16: 1
A17: 8 | B17: KPU | C17: Keo Pu ép góc | D17: lọ | E17: 5
C20: Hà Nội, Ngày 13 tháng 12 năm 2025
A21: Người lập Kiểm tra Kế toán Vật tư Người nhận Duyệt

Sheet PK_L1 
A1: PHIẾU YÊU CẦU VẬT TƯ- PHỤ KIỆN ĐI CÔNG TRÌNH
B2: Ngày ..13..tháng ..12.. năm 2025
A3: Công trình :L1 Ms Vân Anh
A4: Mã Đơn Hàng :
A5: Chủng loại phụ kiện : Viral
A6: Màu sắc : Bạc
A7: Địa chỉ giao hàng : Tại xưởng sản xuất : 36 Đường Miền Đông, Cự Khê Thanh Oai Hà Nội
A9: TT | B9: Mã VT | C9: Tên vật tư | D9: Đơn vị | E9: Số lượng | F9: NCC
B10: CỬA ĐI MỞ QUAY 1 CÁNH : VRA 55 - MỞ NGOÀI | D10: BỘ | E10: 5
A11: 1 | B11: VIRAL.TDVR2 | C11: =VLOOKUP(B11,[1]TỔNG!$D$3:$Q$242,2,0) -> Tay nắm cửa đi (VR2) | D11: bộ | E11: 5
A12: 2 | B12: VIRAL.SKH03-L | C12: =VLOOKUP(B12,[1]TỔNG!$D$3:$Q$242,2,0) -> Bản lề khung - cánh (VRA) - L | D12: chiếc | E12: 9
A13: 3 | B13: VIRAL.SKH03-R | C13: =VLOOKUP(B13,[1]TỔNG!$D$3:$Q$242,2,0) -> Bản lề khung - cánh (VRA) - R | D13: chiếc | E13: 6
A14: 4 | B14: VIRAL.TKDA8530 | C14: =VLOOKUP(B14,[1]TỔNG!$D$3:$Q$242,2,0) -> Thân khóa đa điểm 85/30 (VRA) | D14: chiếc | E14: 5
A15: 5 | B15: VIRAL.LC47.5/32.5 | C15: =VLOOKUP(B15,[1]TỔNG!$D$3:$Q$242,2,0) -> Lõi khóa mở ngoài VRA55 32.5/47.5 | D15: lõi | E15: 5 | F15: ( kèm vít )
A16: 6 | B16: VIRAL.TVRA50 | C16: =VLOOKUP(B16,[1]TỔNG!$D$3:$Q$242,2,0) -> Trục & ốc vít (VRA50) | D16: túi | E16: 5
A17: 7 | B17: VIRAL.DLF09 | C17: =VLOOKUP(B17,[1]TỔNG!$D$3:$Q$242,2,0) -> Miệng đón khóa (cửa đi 1 cánh) - VRA | D17: chiếc | E17: 5
A18: 8 | B18: VIRAL.VITO11 | C18: =VLOOKUP(B18,[1]TỔNG!$D$3:$Q$242,2,0) -> Đầu khóa biên trắng | D18: chiếc | E18: 10
A19: 9 | B19: VIRAL.VITO1 | C19: =VLOOKUP(B19,[1]TỔNG!$D$3:$Q$242,2,0) -> Vấu hãm cửa 1 cánh | D19: chiếc | E19: 10
B20: CỬA ĐI MỞ QUAY 2 CÁNH : VRA 55 - MỞ NGOÀI | D20: BỘ | E20: 1
A21: 1 | B21: VIRAL.TDVR2 | C21: =VLOOKUP(B21,[1]TỔNG!$D$3:$Q$879,2,0) -> Tay nắm cửa đi (VR2) | D21: bộ | E21: 1
A22: 2 | B22: VIRAL.SKH03-L | C22: =VLOOKUP(B22,[1]TỔNG!$D$3:$Q$879,2,0) -> Bản lề khung - cánh (VRA) - L | D22: chiếc | E22: 3
A23: 3 | B23: VIRAL.SKH03-R | C23: =VLOOKUP(B23,[1]TỔNG!$D$3:$Q$879,2,0) -> Bản lề khung - cánh (VRA) - R | D23: chiếc | E23: 3
A24: 4 | B24: VIRAL.TKDA8530 | C24: =VLOOKUP(B24,[1]TỔNG!$D$3:$Q$879,2,0) -> Thân khóa đa điểm 85/30 (VRA) | D24: chiếc | E24: 1
A25: 5 | B25: VIRAL.LC47.5/32.5 | C25: =VLOOKUP(B25,[1]TỔNG!$D$3:$Q$879,2,0) -> Lõi khóa mở ngoài VRA55 32.5/47.5 | D25: lõi | E25: 1 | F25: ( kèm vít )
A26: 6 | B26: VIRAL.TVRA55 | C26: =VLOOKUP(B26,[1]TỔNG!$D$3:$Q$879,2,0) -> Trục & ốc vít (VRA55) | D26: túi | E26: 1
A27: 7 | B27: VIRAL.VITO7 | C27: =VLOOKUP(B27,[1]TỔNG!$D$3:$Q$879,2,0) -> Miệng đón khóa điều chỉnh (cửa đi 2 cánh) - Chung với VRE | D27: chiếc | E27: 1
A28: 8 | B28: A070003 | C28: =VLOOKUP(B28,[1]TỔNG!$D$3:$Q$879,2,0) -> Đầu biên chốt cánh phụ 90mm | D28: bộ | E28: 1
A29: 9 | B29: A020055 | C29: =VLOOKUP(B29,[1]TỔNG!$D$3:$Q$879,2,0) -> Móc chốt cánh phụ 130mm
A30: 10 | B30: D100021 | C30: =VLOOKUP(B30,[1]TỔNG!$D$3:$Q$879,2,0) -> Đệm chốt cánh phụ
A31: 11 | B31: VIRAL.VITO11 | C31: =VLOOKUP(B31,[1]TỔNG!$D$3:$Q$879,2,0) -> Đầu khóa biên trắng | D31: chiếc | E31: 2
A32: 12 | B32: VIRAL.VITO2 | C32: =VLOOKUP(B32,[1]TỔNG!$D$3:$Q$879,2,0) -> Vấu cửa sổ rãnh C (Châu Âu) | D32: chiếc | E32: 2
B33: CỬA SỔ MỞ HẤT 1 CÁNH : VRA 55 | D33: BỘ | E33: 12
A34: 1 | B34: VIRAL.TSVR2 | C34: =VLOOKUP(B34,[1]TỔNG!$D$3:$Q$196,2,0) -> Tay nắm cửa sổ lưỡi gà (VR2) | D34: chiếc | E34: 12
A35: 2 | B35: VIRAL.BANLEA14-22 | C35: =VLOOKUP(B35,[1]TỔNG!$D$3:$Q$196,2,0) -> Bản lề A mở quay rãnh 22 A12 | D35: cặp | E35: 12
A36: 3 | B36: VIRAL.SSC10 | C36: =VLOOKUP(B36,[1]TỔNG!$D$3:$Q$196,2,0) -> Chống gió rút (chống sao) - RÃNH K dài 12 inch | D36: cặp | E36: 12
A37: 4 | B37: VIRAL.VITO10 | C37: =VLOOKUP(B37,[1]TỔNG!$D$3:$Q$196,2,0) -> Đầu T trắng | D37: bộ | E37: 12
A38: 5 | B38: VIRAL.VITO11 | C38: =VLOOKUP(B38,[1]TỔNG!$D$3:$Q$196,2,0) -> Đầu khóa biên trắng
A39: 6 | B39: VIRAL.VITO1 | C39: =VLOOKUP(B39,[1]TỔNG!$D$3:$Q$196,2,0) -> Vấu hãm cửa 1 cánh
A40: 8 | B40: VIRAL.1630FJS-16 | C40: =VLOOKUP(B40,[1]TỔNG!$D$3:$Q$196,2,0) -> Đệm chống sệ | D40: chiếc | E40: 50
C43: Hà Nội, Ngày 13 tháng 12 năm 2025
...

Sheet KH CT VÂN ANH 
A1: PHIẾU YÊU CẦU VẬT TƯ KÍNH
B2: Ngày ..03..tháng ..12.. năm 2025
A3: Công trình : Ms Vân Anh - Thái Bình
A4: Mã Đơn Hàng :
A5: Chủng loại phụ kiện :
A6: Màu sắc :
A7: Địa chỉ giao hàng : 36 Đường Miền Đông, Cự Khê Thanh Oai Hà Nội - SDT :
A9: TT | B9: Mã Kính | C9: Loại kính | D9: Chiều rộng | E9: Chiều cao | F9: ĐVT | G9: Số tấm | H9: Diện tích
A10: 1 | B10: DK1T1-Ms Vân Anh TB | C10: KH 5CL-9A-8.38 mm Solar control BD03 | D10: 337 | E10: 289 | F10: tấm | G10: 2 | H10: =(D10/1000)*(E10/1000)*G10 -> 0.194786
A11: 2 | B11: DK1T1-Ms Vân Anh TB | C11: KH 5CL-9A-8.38 mm Solar control BD03 | D11: 337 | E11: 2243 | F11: tấm | G11: 2 | H11: =(D11/1000)*(E11/1000)*G11 -> 1.511782
A12: 3 | B12: DK1T1-Ms Vân Anh TB | C12: KH 5CL-9A-8.38 mm Solar control BD03 | D12: 1804 | E12: 289 | F12: tấm | G12: 1 | H12: =(D12/1000)*(E12/1000)*G12 -> 0.521356
A13: 4 | B13: DK1T1-Ms Vân Anh TB | C13: KH 5CL-9A-8.38 mm Solar control BD03 | D13: 750 | E13: 2080 | F13: tấm | G13: 2 | H13: =(D13/1000)*(E13/1000)*G13 -> 3.12
A14: 5 | B14: DK2T1-Ms Vân Anh TB | C14: KH 5CL-9A-8.38 mm Solar control BD03 | D14: 1213 | E14: 343 | F14: tấm | G14: 2 | H14: =(D14/1000)*(E14/1000)*G14 -> 0.832118
A15: 6 | B15: DK2T1-Ms Vân Anh TB | C15: KH 5CL-9A-8.38 mm Solar control BD03 | D15: 1113 | E15: 2084 | F15: tấm | G15: 2 | H15: =(D15/1000)*(E15/1000)*G15 -> 4.638984
A16: 15 | B16: DK2.1T2-Ms Vân Anh TB | C16: KH 5CL-9A-8.38 mm Solar control BD03 | D16: 621 | E16: 323 | F16: tấm | G16: 2 | H16: =(D16/1000)*(E16/1000)*G16 -> 0.401166
A17: 16 | B17: DK2.1T2-Ms Vân Anh TB | C17: KH 5CL-9A-8.38 mm Solar control BD03 | D17: 621 | E17: 2249 | F17: tấm | G17: 2 | H17: =(D17/1000)*(E17/1000)*G17 -> 2.793258
A18: 17 | B18: DK2.1T2-Ms Vân Anh TB | C18: KH 5CL-9A-8.38 mm Solar control BD03 | D18: 1813 | E18: 323 | F18: tấm | G18: 1 | H18: =(D18/1000)*(E18/1000)*G18 -> 0.585599
A19: 18 | B19: DK2.1T2-Ms Vân Anh TB | C19: KH 5CL-9A-8.38 mm Solar control BD03 | D19: 740 | E19: 2083 | F19: tấm | G19: 2 | H19: =(D19/1000)*(E19/1000)*G19 -> 3.08284
A20: 19 | B20: W2.1T2-Ms Vân Anh TB | C20: KH 5CL Phun cát -9A-8.38 mm Solar control BD03 | D20: 1139 | E20: 1197 | F20: tấm | G20: 1 | H20: =(D20/1000)*(E20/1000)*G20 -> 1.363383
A21: 20 | B21: W2.1T2-Ms Vân Anh TB | C21: KH 5CL-9A-8.38 mm Solar control BD03 | D21: 469 | E21: 1133 | F21: tấm | G21: 2 | H21: =(D21/1000)*(E21/1000)*G21 -> 1.062754
A22: 32 | B22: DK3.1T3-Ms Vân Anh TB | C22: KH 5CL-9A-8.38 mm Solar control BD03 | D22: 933 | E22: 2774 | F22: tấm | G22: 6 | H22: =(D22/1000)*(E22/1000)*G22 -> 15.528852
B23: TỔNG | G23: =SUM(G10:G22) -> 27 | H23: =SUM(H10:H22) -> 35.636878
C24: Hà Nội, Ngày 04 tháng 12 năm 2025
A26: Người lập Kiểm tra Kế toán Vật tư Người nhận Duyệt
A27: (Ký, họ tên) (Ký, họ tên) (Ký, họ tên) (Ký, họ tên) (Ký, họ tên) (Ký, họ tên)

Sheet KD_VÂN ANH 
A1: PHIẾU YÊU CẦU VẬT TƯ KÍNH
B2: Ngày ..03..tháng ..12.. năm 2025
A3: Công trình : Ms Vân Anh - Thái Bình
A4: Mã Đơn Hàng :
A5: Chủng loại phụ kiện :
A6: Màu sắc :
A7: Địa chỉ giao hàng : 36 Đường Miền Đông, Cự Khê Thanh Oai Hà Nội - SDT :
A9: TT | B9: Mã Kính | C9: Loại kính | D9: Chiều rộng | E9: Chiều cao | F9: ĐVT | G9: Số tấm | H9: Diện tích
A10: 7 | B10: DK3T1-Ms Vân Anh TB | C10: 8.38 mm trắng trong | D10: 816 | E10: 328 | F10: tấm | G10: 1 | H10: =(D10/1000)*(E10/1000)*G10 -> 0.267648
A11: 8 | B11: DK3T1-Ms Vân Anh TB | C11: 8.38 mm trắng trong | D11: 650 | E11: 2077 | F11: tấm | G11: 1 | H11: =(D11/1000)*(E11/1000)*G11 -> 1.35005
A12: 9 | B12: S1T1-Ms Vân Anh TB | C12: 6.38 mm trắng trong | D12: 446 | E12: 1421 | F12: tấm | G12: 1 | H12: =(D12/1000)*(E12/1000)*G12 -> 0.633766
A13: 10 | B13: S2T1-Ms Vân Anh TB | C13: 6.38 mm trắng trong | D13: 451 | E13: 1418 | F13: tấm | G13: 1 | H13: =(D13/1000)*(E13/1000)*G13 -> 0.639518
A14: 11 | B14: S3T1-Ms Vân Anh TB | C14: 6.38 mm trắng trong | D14: 440 | E14: 1142 | F14: tấm | G14: 2 | H14: =(D14/1000)*(E14/1000)*G14 -> 1.00496
A15: 12 | B15: S3T1-Ms Vân Anh TB | C15: 6.38 mm trắng trong | D15: 1132 | E15: 328 | F15: tấm | G15: 1 | H15: =(D15/1000)*(E15/1000)*G15 -> 0.371296
A16: 13 | B16: S4T1-Ms Vân Anh TB | C16: 6.38 mm trắng trong | D16: 1242 | E16: 328 | F16: tấm | G16: 1 | H16: =(D16/1000)*(E16/1000)*G16 -> 0.407376
A17: 14 | B17: S4T1-Ms Vân Anh TB | C17: 6.38 mm trắng trong | D17: 533 | E17: 1122 | F17: tấm | G17: 2 | H17: =(D17/1000)*(E17/1000)*G17 -> 1.196052
A18: 21 | B18: W2.2T2-Ms Vân Anh TB | C18: 8.38 mm trắng trong | D18: 858 | E18: 328 | F18: tấm | G18: 1 | H18: =(D18/1000)*(E18/1000)*G18 -> 0.281424
A19: 22 | B19: W2.2T2-Ms Vân Anh TB | C19: 8.38 mm trắng trong | D19: 832 | E19: 328 | F19: tấm | G19: 1 | H19: =(D19/1000)*(E19/1000)*G19 -> 0.272896
A20: 23 | B20: W2.2T2-Ms Vân Anh TB | C20: 8.38 mm trắng trong | D20: 756 | E20: 1322 | F20: tấm | G20: 1 | H20: =(D20/1000)*(E20/1000)*G20 -> 0.999432
A21: 24 | B21: W2.2T2-Ms Vân Anh TB | C21: 8.38 mm trắng trong | D21: 666 | E21: 2101 | F21: tấm | G21: 1 | H21: =(D21/1000)*(E21/1000)*G21 -> 1.399266
... A37: 41 | B37: SCTT3-Ms Vân Anh TB | C37: 6.38 mm trắng trong | D37: 726 | E37: 1252 | F37: tấm | G37: 1 | H37: =(D37/1000)*(E37/1000)*G37 -> 0.908952
B38: TỔNG | G38: =SUM(G10:G37) -> 30 | H38: =SUM(H10:H37) -> 20.60231
C39: Hà Nội, Ngày 04 tháng 12 năm 2025
A41: Người lập Kiểm tra Kế toán Vật tư Người nhận Duyệt
A42: (Ký, họ tên) (Ký, họ tên) (Ký, họ tên) (Ký, họ tên) (Ký, họ tên) (Ký, họ tên)

Sheet NHÔM_L2
A1: PHIẾU YÊU CẦU VẬT TƯ- PHỤ KIỆN
A2: Công trình :Ms Vân Anh - Thái Bình
A3: Mã Đơn Hàng :
A4: Chủng loại phụ kiện :
A5: Màu sắc : Xám Sần Metalic
A6: Địa chỉ giao hàng :
A8: TT | B8: Tên vật tư | C8: Mã vật tư | D8: Tỷ trọng | E8: Đơn vị | F8: Số lượng | G8: Khối lượng | H8: Ghi chú
A9: 14 | B9: Khung bao vách 65 | C9: Y6501 | D9: 1.477 | E9: cây | F9: 5 | G9: =F9*6*D9 -> 44.31 | H9: Dmax
A10: 15 | B10: Cánh cửa đi mở ngoài 65 | C10: Y6503 | D10: 1.813 | E10: cây | F10: 3 | G10: =F10*6*D10 -> 32.634 | H10: Dmax
A11: 16 | B11: Nối khung | C11: Y6511 | D11: 0.415 | E11: cây | F11: 3 | G11: =F11*6*D11 -> 7.47
A12: 17 | B12: Đố động dùng chung 65 | C12: Y6507 | D12: 1.09 | E12: cây | F12: 1 | G12: =F12*6*D12 -> 6.54
A13: 18 | B13: Ngưỡng nhôm | C13: C6517 | D13: 1.18 | E13: cây | F13: 1 | G13: =F13*6*D13 -> 7.08 | H13: ALUK
A14: 19 | B14: Che chân | C14: C6518 | D14: 0.23 | E14: cây | F14: 1 | G14: =F14*6*D14 -> 1.38 | H14: ALUK
A15: 20 | B15: Đố T chi vách | C15: Y6506 | D15: 1.269 | E15: cây | F15: 1 | G15: =F15*6*D15 -> 7.614 | H15: Tận dụng DC
A16: 21 | B16: Nẹp kính hộp | C16: Y6513 | D16: 0.283 | E16: cây | F16: 6 | G16: =F16*6*D16 -> 10.188
A17: 22 | B17: Khung bao lùa 120 | C17: YL12001 | D17: 2 | E17: cây | F17: 2 | G17: =F17*6*D17 -> 24
A18: 23 | B18: Dẫn hướng trên 120 | C18: YL12003 | D18: 0.86 | E18: cây | F18: 1 | G18: =F18*6*D18 -> 5.16
A19: 24 | B19: Ôp khung bao đứng trong 120 | C19: YL12004 | D19: 1.22 | E19: cây | F19: 1 | G19: =F19*6*D19 -> 7.32
A20: 25 | B20: Ôp khung bao đứng ngoài 120 | C20: YL12005 | D20: 1.158 | E20: cây | F20: 1 | G20: =F20*6*D20 -> 6.948
A21: 26 | B21: Ôp móc 120 | C21: YL12006 | D21: 0.47 | E21: cây | F21: 5 | G21: =F21*6*D21 -> 14.1
A22: 27 | B22: Khung bao vách 120 | C22: YL12009 | D22: 1.48 | E22: cây | F22: 1 | G22: =F22*6*D22 -> 8.88
A23: 28 | B23: Cánh cửa lùa 120 | C23: YL12006 | D23: 2.02 | E23: cây | F23: =3+9 -> 12 | G23: =F23*6*D23 -> 145.44
A24: 29 | B24: Hèm 4 cánh 120 | C24: YL12008 | D24: 0.476 | E24: cây | F24: 1 | G24: =F24*6*D24 -> 2.856
A25: 30 | B25: Đố T chia vách 120 | C25: YL12010 | D25: 0.97 | E25: cây | F25: 1 | G25: =F25*6*D25 -> 5.82 | H25: Tận dụng DC
A26: 31 | B26: Khung bao đứng 180 | C26: YL18001 | D26: 2.82 | E26: cây | F26: 4 | G26: =F26*6*D26 -> 67.68
A27: 32 | B27: Nối dẫn hướng trên 180 | C27: YL18004 | D27: 0.438 | E27: cây | F27: 2 | G27: =F27*6*D27 -> 5.256
A28: 33 | B28: Nối ốp khung bao đứng trong 180 | C28: YL18003 | D28: 0.615 | E28: cây | F28: 1 | G28: =F28*6*D28 -> 3.69
A29: 34 | B29: Nối ốp khung bao đứng ngoài 180 | C29: YL18007 | D29: 0.632 | E29: cây | F29: 1 | G29: =F29*6*D29 -> 3.792
A30: 35 | B30: Khung bao 94 | C30: VRE94-01 | D30: 1.425 | E30: cây | F30: 1 | G30: =F30*6*D30 -> 8.55
A31: 36 | B31: Cánh cửa lùa 94 | C31: VRE94-02 | D31: 1.235 | E31: cây | F31: 2 | G31: =F31*6*D31 -> 14.82
A32: 37 | B32: Dẫn hướng trên 94 | C32: LINDT21 | D32: 0.22 | E32: cây | F32: 1 | G32: =F32*6*D32 -> 1.32
A33: 38 | B33: Đón cánh bên 94 | C33: LINH17 | D33: 0.22 | E33: cây | F33: 1 | G33: =F33*6*D33 -> 1.32
A34: 39 | B34: Op khung bao 94 | C34: VRE94-06 | D34: 0.293 | E34: cây | F34: 1 | G34: =F34*6*D34 -> 1.758
A35: 40 | B35: Op móc 94 | C35: VRE94-04 | D35: 0.443 | E35: cây | F35: 1 | G35: =F35*6*D35 -> 2.658
A36: 41 | B36: Khung fix 94 | C36: VRE94-05 | D36: 1.24 | E36: cây | F36: 1 | G36: =F36*6*D36 -> 7.44
A37: 42 | B37: Khung bao 64 | C37: VRA64-01 | D37: 1.425 | E37: cây | F37: 1 | G37: =F37*6*D37 -> 8.55
A38: 43 | B38: Cánh lùa 64 | C38: VRA64-02 | D38: 1.155 | E38: cây | F38: 2 | G38: =F38*6*D38 -> 13.86
A39: 44 | B39: Ôp móc 64 | C39: VRA64-03 | D39: 0.42 | E39: cây | F39: 1 | G39: =F39*6*D39 -> 2.52 | H39: Lumal
B40: TỔNG CỘNG | G40: =SUM(G9:G39) -> 480.954

Sheet PK_L2 
A1: PHIẾU YÊU CẦU VẬT TƯ- PHỤ KIỆN ĐI CÔNG TRÌNH
B2: Ngày ..03..tháng ..12.. năm 2025
A3: Công trình : Ms Vân Anh
A4: Mã Đơn Hàng :
A5: Chủng loại phụ kiện : Viral
A6: Màu sắc : Bạc
A7: Địa chỉ giao hàng : Tại xưởng sản xuất : 36 Đường Miền Đông, Cự Khê Thanh Oai Hà Nội
A9: TT | B9: Mã VT | C9: Tên vật tư | D9: Đơn vị | E9: Số lượng | F9: NCC
B10: CỬA ĐI MỞ QUAY 2 CÁNH : VRE 65 - MỞ NGOÀI | D10: BỘ | E10: 1
A11: 1 | B11: VIRAL.TDVR2 | C11: =VLOOKUP(B11,[1]TỔNG!$D$3:$Q$879,2,0) -> Tay nắm cửa đi (VR2) | D11: bộ | E11: 1
A12: 5 | B12: VIRAL.LC30/70 | C12: =VLOOKUP(B12,[1]TỔNG!$D$3:$Q$879,2,0) -> Lõi khóa mở ngoài hệ VRE65 32.5/70 | D12: lõi | E12: 1 | F12: ( kèm vít ) - vina
A13: 6 | B13: VIRAL.TVRE65 | C13: =VLOOKUP(B13,[1]TỔNG!$D$3:$Q$879,2,0) -> Trục & ốc vít (VRE65) | D13: túi | E13: 1 | F13: 1 trục 65 + 2 vít tay nắm 65 - vina
A14: 7 | B14: VIRAL.VITO7 | C14: =VLOOKUP(B14,[1]TỔNG!$D$3:$Q$879,2,0) -> Miệng đón khóa điều chỉnh (cửa đi 2 cánh) - Chung với VRE | D14: chiếc | E14: 1
A15: 11 | B15: VIRAL.SKP04 | C15: =VLOOKUP(B15,[1]TỔNG!$D$3:$Q$879,2,0) -> Bộ chuyển động 4 thứ - cửa sổ (VRE) | D15: bộ | E15: 1 | F15: Cấp rời 2 vấu
B16: CỬA ĐI MỞ LÙA 2 CÁNH : VRE 120 | D16: BỘ | E16: 1
A17: 1 | B17: VIRAL.CL450 | C17: Tay nắm cửa lùa 450 | D17: chiếc | E17: 4
A18: 2 | B18: VIRAL.PTDA8530 | C18: =VLOOKUP(B18,[1]TỔNG!$D$3:$Q$242,2,0) -> Thân khóa lùa đa điểm -Móc đôi. (Thân+ miệng đón khóa) | D18: chiếc | E18: 2 | F18: kiểm tra lắp lên cửa chưa - miệng xuất rời
A19: 3 | B19: VIRAL.NL | C19: =VLOOKUP(B19,[1]TỔNG!$D$3:$Q$242,2,0) -> Nắp chụp ruột khóa Viral (Nắp lõi khoá) | D19: túi | E19: 2
A20: 4 | B20: VIRAL.LC35/35 | C20: =VLOOKUP(B20,[1]TỔNG!$D$3:$Q$242,2,0) -> Lõi khóa cửa lùa (VRE120) Lõi cân 35/35(37/37) | D20: lõi | E20: 2
A21: 7 | B21: VIRAL.FKD | C21: =VLOOKUP(B21,[1]TỔNG!$D$3:$Q$242,2,0) -> Chống đập cánh | D21: chiếc | E21: 2
B22: CỬA ĐI MỞ LÙA 6 CÁNH : VRE 180 | D22: BỘ | E22: 1
A23: 3 | B23: VIRAL.CL450 | C23: Tay nắm cửa lùa 450mm | D23: chiếc | E23: 4
A24: 4 | B24: VIRAL.PTDA8530 | C24: =VLOOKUP(B24,[1]TỔNG!$D$3:$Q$242,2,0) -> Thân khóa lùa đa điểm -Móc đôi. (Thân+ miệng đón khóa) | D24: chiếc | E24: 1 | F24: kiểm tra lắp lên cửa chưa - miệng xuất rời
A25: 5 | B25: VIRAL.NL | C25: =VLOOKUP(B25,[1]TỔNG!$D$3:$Q$242,2,0) -> Nắp chụp ruột khóa Viral (Nắp lõi khoá) | D25: túi
A26: 6 | B26: VIRAL.LC35/35 | C26: =VLOOKUP(B26,[1]TỔNG!$D$3:$Q$242,2,0) -> Lõi khóa cửa lùa (VRE120) Lõi cân 35/35(37/37) | D26: chiếc | E26: 1 | F26: kèm vít lõi khóa
A27: 9 | B27: VIRAL.FKD | C27: =VLOOKUP(B27,[1]TỔNG!$D$3:$Q$242,2,0) -> Chống đập cánh | D27: chiếc | E27: 4
B28: VHCL | C28: Vấu hàm cửa lùa bắt trên khung | D28: chiếc | E28: 4
B29: CỬA SỔ MỞ LÙA 2 CÁNH : VRA 64 | D29: BỘ | E29: 1
A30: 5 | B30: VIRAL.CDK | C30: =VLOOKUP(B30,[1]TỔNG!$D$3:$Q$242,2,0) -> Giảm chấn (Núm cao su) | D30: chiếc | E30: 4
A31: 6 | B31: VIRAL.FKD | C31: =VLOOKUP(B31,[1]TỔNG!$D$3:$Q$242,2,0) -> Chống đập cánh | D31: chiếc | E31: 2
A32: 7 | B32: VIRAL.BINH2 | C32: =VLOOKUP(B32,[1]TỔNG!$D$3:$Q$242,2,0) -> Dẫn hướng cửa lùa VRA | D32: chiếc | E32: 4
B33: VHCL | C33: Vấu hàm cửa lùa bắt trên khung | D33: chiếc | E33: 4
B34: CỬA SỔ MỞ LÙA 2 CÁNH : VRE 94 | D34: BỘ | E34: 1
A35: 6 | B35: VIRAL.FKD | C35: =VLOOKUP(B35,[1]TỔNG!$D$3:$Q$242,2,0) -> Chống đập cánh | D35: chiếc | E35: 2
B36: VHCL | C36: Vấu hàm cửa lùa bắt trên khung | D36: chiếc | E36: 4
C39: Hà Nội, Ngày 04 tháng 12 năm 2025
A41: Người lập Kiểm tra Kế toán Vật tư Người nhận Duyệt
A42: (Ký, họ tên) (Ký, họ tên) (Ký, họ tên) (Ký, họ tên) (Ký, họ tên) (Ký, họ tên)

Sheet PHIỄU XUÂT KHO 
A1: CÔNG TY CỔ PHẦN VIRALWINDOW
A2: Nhà máy: KM 03, Đường Cienco5, KĐT Thanh Hà, Hà Đông, Hà Nội
A3: Hotline: 1800 282839
A4: Email: viralwindow.vn@gmail.com
A5: Website: viralwindow.vn
A6: PHIẾU XUẤT KHO
A7: Số: 00-VRT12
B8: Khách hàng : Anh Hiền - Đô Lương | E8: Đại lý:
B9: Ký hiệu :
B10: Địa chỉ : Văn Sơn - Đô Lương - Nghệ An
B11: Số điện thoại:
B12: Lý do xuất : Xuất trả hàng
B13: Xuất tại kho: Công ty cổ phần Viralwindow ,Số 36 Đường Miền Đông Cự Khê Thanh Oai Hà Nội
B14: Thời điểm vận chuyển :
A15: STT | B15: Mã hiệu | C15: Nội dung | D15: Kích thước | F15: ĐVT | G15: Tổng số lượng | H15: Diện Tích | I15: Ghi chú
D16: Rộng (mm) | E16: Cao (mm)
B22: CỘNG | G22: =SUM(G17:G21) -> 0 | H22: =SUM(H17:H21) -> 0
D23: 'Hà Nội, Ngày .. tháng 12 năm 2025
A24: Vận chuyển Người kiểm hàng Khách hàng Kế toán Người lập phiếu
