Workbook

Sheet METALIC - SẦN
B1: Nhôm Viralwindow | D1: XÁM SẦN
A2: STT | B2: TÊN GỌI | C2: MÃ CÂY | D2: MẶT CẮT | E2: TỒN ĐẦU KỲ
A3: 1 | B3: VRA-Hệ 55 Mở quay
A4: 2 | B4: Khung vách | C4: C3209 | E4: 6
A5: 3 | B5: Khung bao cửa sổ mở quay | C5: C3318 | E5: 2
A6: 4 | B6: Cây đảo khuôn bao | C6: C3208 | E6: 8
A7: 5 | B7: Cánh cửa sổ mở ngoài | C7: C3202 | E7: 3
A8: 6 | B8: Đố tĩnh chia Khung cửa sổ | C8: C3313 | E8: 5
A9: 7 | B9: Đố tĩnh chia cánh | C9: C3203 | E9: 6
A10: 8 | B10: Đố động cửa sổ | C10: C3033 | E10: 0
A11: 9 | B11: Khung bao cửa đi | C11: C3328 | E11: 22
A12: 10 | B12: Cánh cửa đi mở ngoài | C12: C3303 | E12: 12
A13: 11 | B13: Cánh cửa đi mở trong | C13: C3332 | E13: 19
A14: 12 | B14: Đố ngang dưới cánh cửa đi | C14: C3304 | E14: 8
A15: 13 | B15: Đố động cửa đi | C15: C3323 | E15: 16
... A29: 27 | B29: Nan chớp | C29: E192 | E29: 0
A30: 28 | B30: VRA-Hệ 50 | E30: 0
A31: 29 | B31: Cánh cửa sổ | C31: B46 | E31: 0
A32: 30 | B32: Cánh cửa đi | C32: B45 | E32: 0
A33: 31 | B33: Chia ô nhỏ | C33: Q56A | E33: 0
A34: 32 | B34: VRA-Hệ 64 Cửa sổ lùa | E34: 0
A35: 33 | B35: Khung cửa lùa | C35: 55601 | E35: 0
A36: 34 | B36: Cánh cửa lùa | C36: 55602 | E36: 2
A37: 35 | B37: Ốp móc cửa lùa | C37: 55603 | E37: 1
A38: 36 | B38: Đối đầu | E38: 0
A39: 37 | B39: VRA-Hệ 95 Cửa đi lùa | E39: 0
A40: 38 | B40: Khung cửa lùa | C40: D9302 | E40: 0
A41: 39 | B41: Khung cửa lùa | C41: D9302B | E41: 0
A42: 40 | B42: Khung cửa lùa | C42: D9502 | E42: 0
A43: 41 | B43: Khung cửa lùa | C43: D9521 | E43: 0
A44: 42 | B44: Cánh cửa lùa | C44: D9301B | E44: 0
A45: 43 | B45: Ốp móc cửa lùa | C45: D9306B | E45: 0
A46: 44 | B46: Hèm đối đầu | C46: D9307 | E46: 0
A47: 45 | B47: Bịt khung | C47: D9303 | E47: 0
A48: 46 | B48: Bịt khung | C48: D9303B | E48: 0
A49: 47 | B49: Dẫn hướng | C49: D9305 | E49: 0
A50: 48 | B50: Khung fix | C50: D9519 | E50: 0
A51: 49 | B51: Nẹp khung fix cửa lùa | C51: C101 | E51: 0
A52: 50 | B52: Nẹp sập khung nhỏ | C52: D9304 | E52: 0
A53: 51 | B53: VRE-Hệ 55 Mở quay | E53: 0
...

Sheet Viralwindow --DC
A1: Bảng nhôm Nhôm Viralwindow-Màu Xám Sần
G2: Ngày 13 thàng 07 năm 2021
A3: Tên gọi | B3: Mã cây | C3: Mặt Cắt | D3: Số lượng cây | E3: >500 | F3: 500-1000 | G3: 1000-1500 | H3: 1500-2000 | I3: 2000-2500 | J3: 2500-3000 | K3: 3000-3500 | L3: 3500-4000 | M3: 4000-4500 | N3: 4500-5000 | O3: Chú ý
A4: VRA-Hệ 55 Mở quay
A5: Khung vách | B5: C3209 | D5: =6+6+6+6+6+6 -> 36
A6: Khung bao cửa sổ mở quay | B6: C3318 | D6: =1+5+6+1+6+6 -> 25 | K6: 1 | M6: 1
A7: Cây đảo khuôn bao | B7: C3208 | D7: 10 | M7: 1
A8: Cánh cửa sổ mở ngoài | B8: C3202 | D8: 33
A9: Đố tĩnh chia Khung cửa sổ | B9: C3313 | D9: 5
A10: Đố tĩnh chia cánh | B10: C3203 | D10: 10
A11: Đố động cửa sổ | B11: C3033
A12: Khung bao cửa đi | B12: C3328 | D12: =36+4 -> 40
A13: Cánh cửa đi mở ngoài | B13: C3303 | D13: 23 | L13: 1
A14: Cánh cửa đi mở trong | B14: C3332 | D14: 14
A15: Đố ngang dưới cánh cửa đi | B15: C3304 | D15: 14
A16: Đố động cửa đi | B16: C3323 | D16: 20
A17: Ốp chân cánh cửa đi | B17: C3329 | D17: 10
A18: Nẹp kính đơn >12mm | B18: C3295 | D18: =40+16*3+2 -> 90
A19: Nẹp kính khung bao | B19: C3296
A20: Nẹp kính hộp >22mm | B20: C3236
A21: Nẹp kính hộp >25mm | B21: C3286
A22: Sập kính hộp cho khung > 21mm | B22: C3225
A23: Thanh chuyển góc 90 độ | B23: C3326 | D23: 5
A24: Thanh tăng cứng vách và cửa | B24: C3310
A25: Cây chuyển góc 135 độ | B25: C910
A26: Thanh ghép 2mm | B26: C3300 | D26: 20
A27: Pano | B27: F077
A28: Ngưỡng cửa đi | B28: C3319
A29: Khung chớp | B29: E1283
A30: Nan chớp | B30: E192
A31: VRA-Hệ 64 Cửa sổ lùa
A32: Khung cửa lùa | B32: 55601
A33: Cánh cửa lùa | B33: 55602 | D33: 2
A34: Ốp móc cửa lùa | B34: 55603 | D34: 1
A35: Đối đầu
A36: VRA-Hệ 95 Cửa đi lùa
A37: Khung cửa lùa | B37: D9302
A38: Khung cửa lùa | B38: D9302B
A39: Khung cửa lùa | B39: D9502 | D39: 2 | L39: 1
A40: Khung cửa lùa | B40: D9521
...

Sheet TỒN KHO
H1: =H128*1.05 -> 0 | I1: =I128 -> 398 | J1: =J128 -> 0 | K1: =K128 -> 940 | L1: =L128*1.05 -> 4777.0443
A2: STT | B2: TÊN GỌI | C2: MÃ CÂY | D2: MẶT CẮT | E2: MÀU SẮC | F2: TỶ TRỌNG THÔ | G2: tồn kho kiểm ngày 18.11 (cây) | H2: TỒN ĐẦU KỲ THEO KG | I2: NHẬP | J2: XUẤT | K2: TỒN CUỐI KỲ VIRAL (cây) | L2: TỒN CUỐI KỲ THEO KG | M2: TỒN BÊN KHO YANGLY | N2: GHI CHÚ | O2: SO SÁNH
A3: Nhà CC | I3: =I122+I111+I96+I71+I62+I49+I46+I42+I38+I5 -> 398 | J3: =J5+J38+J42+J46+J49+J62+J71+J96+J111+J122 -> 230 | K3: 4=1+2+3 | L3: A*4*6m
A4: Ngày
A5: I | B5: VRA-Hệ 55 Mở quay | E5: Xám sần | G5: =SUM(G6:G37) -> 354 | H5: =SUM(H6:H37) -> 1392.006 | I5: =SUM(I6:I37) -> 85 | J5: =SUM(J6:J37) -> 85 | K5: =SUM(K6:K37) -> 354 | L5: =SUM(L6:L37) -> 1380.684 | N5: =SUM(N6:N37) -> 0 | O5: =SUM(O6:O37) -> 0
A6: 1 | B6: Khung vách | C6: C3209 | E6: Xám sần | F6: 0.842 | G6: 15 | H6: =F6*G6*6 -> 75.78 | I6: =VLOOKUP(C6,'NHẬP KHO '!C:U,18,0) -> 26 | J6: =VLOOKUP(C6,'XUẤT KHO'!C:Z,23,0) -> 6 | K6: =G6+I6-J6 -> 35 | L6: =F6*K6*6 -> 176.82
A7: 2 | B7: Khung bao cửa sổ mở quay | C7: C3318 | E7: Xám sần | F7: 0.887 | G7: 8 | H7: =F7*G7*6 -> 42.576 | I7: =VLOOKUP(C7,'NHẬP KHO '!C:U,18,0) -> 0 | J7: =VLOOKUP(C7,'XUẤT KHO'!C:Z,23,0) -> 3 | K7: =G7+I7-J7 -> 5 | L7: =F7*K7*6 -> 26.61
A8: 3 | B8: Cây đảo khuôn bao | C8: C3208 | E8: Xám sần | F8: 0.798 | H8: =F8*G8*6 -> 0 | I8: =VLOOKUP(C8,'NHẬP KHO '!C:U,18,0) -> 0 | J8: =VLOOKUP(C8,'XUẤT KHO'!C:Z,23,0) -> 0 | K8: =G8+I8-J8 -> 0 | L8: =F8*K8*6 -> 0
A9: 4 | B9: Cánh cửa sổ mở ngoài | C9: C3202P | E9: Xám sần | F9: 1.127 | G9: 1 | H9: =F9*G9*6 -> 6.762 | I9: =VLOOKUP(C9,'NHẬP KHO '!C:U,18,0) -> 0 | J9: =VLOOKUP(C9,'XUẤT KHO'!C:Z,23,0) -> 0 | K9: =G9+I9-J9 -> 1 | L9: =F9*K9*6 -> 6.762
A10: 5 | B10: Đố tĩnh chia Khung cửa sổ | C10: C3313 | E10: Xám sần | F10: 1.056 | G10: 11 | H10: =F10*G10*6 -> 69.696 | I10: =VLOOKUP(C10,'NHẬP KHO '!C:U,18,0) -> 0 | J10: =VLOOKUP(C10,'XUẤT KHO'!C:Z,23,0) -> 0 | K10: =G10+I10-J10 -> 11 | L10: =F10*K10*6 -> 69.696
A11: 6 | B11: Đố tĩnh chia cánh | C11: C3203 | E11: Xám sần | F11: 1.001 | G11: 9 | H11: =F11*G11*6 -> 54.054 | I11: =VLOOKUP(C11,'NHẬP KHO '!C:U,18,0) -> 0 | J11: =VLOOKUP(C11,'XUẤT KHO'!C:Z,23,0) -> 1 | K11: =G11+I11-J11 -> 8 | L11: =F11*K11*6 -> 48.048
A12: 7 | B12: Khung bao cửa đi | C12: C3328 | E12: Xám sần | F12: 1.286 | G12: 18 | H12: =F12*G12*6 -> 138.888 | I12: =VLOOKUP(C12,'NHẬP KHO '!C:U,18,0) -> 0 | J12: =VLOOKUP(C12,'XUẤT KHO'!C:Z,23,0) -> 4 | K12: =G12+I12-J12 -> 14 | L12: =F12*K12*6 -> 108.024
A13: 8 | B13: Cánh cửa đi mở ngoài | C13: C3303P | E13: Xám sần | F13: 1.496 | H13: =F13*G13*6 -> 0 | I13: =VLOOKUP(C13,'NHẬP KHO '!C:U,18,0) -> 0 | J13: =VLOOKUP(C13,'XUẤT KHO'!C:Z,23,0) -> 0 | K13: =G13+I13-J13 -> 0 | L13: =F13*K13*6 -> 0
A14: 9 | B14: Cánh cửa đi mở trong | C14: C3332P | E14: Xám sần | F14: 1.496 | G14: 12 | H14: =F14*G14*6 -> 107.712 | I14: =VLOOKUP(C14,'NHẬP KHO '!C:U,18,0) -> 0 | J14: =VLOOKUP(C14,'XUẤT KHO'!C:Z,23,0) -> 0 | K14: =G14+I14-J14 -> 12 | L14: =F14*K14*6 -> 107.712
A15: 10 | B15: Đố ngang dưới cánh cửa đi | C15: C3304P | E15: Xám sần | F15: 2.107 | H15: =F15*G15*6 -> 0 | I15: =VLOOKUP(C15,'NHẬP KHO '!C:U,18,0) -> 0 | J15: =VLOOKUP(C15,'XUẤT KHO'!C:Z,23,0) -> 0 | K15: =G15+I15-J15 -> 0 | L15: =F15*K15*6 -> 0
A16: 11 | B16: Đố động cửa đi và cửa sổ nhập Yangly | C16: C3323 | E16: Xám sần | F16: 0.828 | G16: 24 | H16: =F16*G16*6 -> 119.232 | I16: =VLOOKUP(C16,'NHẬP KHO '!C:U,18,0) -> 0 | J16: =VLOOKUP(C16,'XUẤT KHO'!C:Z,23,0) -> 1 | K16: =G16+I16-J16 -> 23 | L16: =F16*K16*6 -> 114.264
A17: 12 | B17: Ốp chân cánh cửa đi | C17: C3329 | E17: Xám sần | F17: 0.448 | H17: =F17*G17*6 -> 0 | I17: =VLOOKUP(C17,'NHẬP KHO '!C:U,18,0) -> 0 | J17: =VLOOKUP(C17,'XUẤT KHO'!C:Z,23,0) -> 0 | K17: =G17+I17-J17 -> 0 | L17: =F17*K17*6 -> 0
A18: 13 | B18: Nẹp kính đơn >12mm | C18: C3295 | E18: Xám sần | F18: 0.238 | G18: 11 | H18: =F18*G18*6 -> 15.708 | I18: =VLOOKUP(C18,'NHẬP KHO '!C:U,18,0) -> 0 | J18: =VLOOKUP(C18,'XUẤT KHO'!C:Z,23,0) -> 8 | K18: =G18+I18-J18 -> 3 | L18: =F18*K18*6 -> 4.284
A19: 14 | B19: Nẹp kính khung bao | C19: C3296 | E19: Xám sần | F19: 0.246 | H19: =F19*G19*6 -> 0 | I19: =VLOOKUP(C19,'NHẬP KHO '!C:U,18,0) -> 0 | J19: =VLOOKUP(C19,'XUẤT KHO'!C:Z,23,0) -> 0 | K19: =G19+I19-J19 -> 0 | L19: =F19*K19*6 -> 0
A20: 15 | B20: Nẹp kính hộp >22mm | C20: C3236 | E20: Xám sần | F20: 0.238 | G20: 7 | H20: =F20*G20*6 -> 9.996 | I20: =VLOOKUP(C20,'NHẬP KHO '!C:U,18,0) -> 0 | J20: =VLOOKUP(C20,'XUẤT KHO'!C:Z,23,0) -> 1 | K20: =G20+I20-J20 -> 6 | L20: =F20*K20*6 -> 8.568
A21: 16 | B21: Nẹp kính hộp >25mm | C21: C3286 | E21: Xám sần | F21: 0.238 | G21: 30 | H21: =F21*G21*6 -> 42.84 | I21: =VLOOKUP(C21,'NHẬP KHO '!C:U,18,0) -> 0 | J21: =VLOOKUP(C21,'XUẤT KHO'!C:Z,23,0) -> 0 | K21: =G21+I21-J21 -> 30 | L21: =F21*K21*6 -> 42.84
A22: 17 | B22: Sập kính hộp cho khung > 21mm | C22: C3225 | E22: Xám sần | F22: 0.233 | H22: =F22*G22*6 -> 0 | I22: =VLOOKUP(C22,'NHẬP KHO '!C:U,18,0) -> 0 | J22: =VLOOKUP(C22,'XUẤT KHO'!C:Z,23,0) -> 0 | K22: =G22+I22-J22 -> 0 | L22: =F22*K22*6 -> 0
A23: 18 | B23: Thanh chuyển góc 90 độ (góc vát) | C23: C3326 | E23: Xám sần | F23: 0.933 | G23: 2 | H23: =F23*G23*6 -> 11.196 | I23: =VLOOKUP(C23,'NHẬP KHO '!C:U,18,0) -> 0 | J23: =VLOOKUP(C23,'XUẤT KHO'!C:Z,23,0) -> 0 | K23: =G23+I23-J23 -> 2 | L23: =F23*K23*6 -> 11.196
A24: 19 | B24: Thanh tăng cứng vách và cửa | C24: C3310 | E24: Xám sần | F24: 1.371 | G24: 2 | H24: =F24*G24*6 -> 16.452 | I24: =VLOOKUP(C24,'NHẬP KHO '!C:U,18,0) -> 0 | J24: =VLOOKUP(C24,'XUẤT KHO'!C:Z,23,0) -> 0 | K24: =G24+I24-J24 -> 2 | L24: =F24*K24*6 -> 16.452
A25: 20 | B25: Cây chuyển góc 135 độ | C25: C910 | E25: Xám sần | F25: 0.962 | H25: =F25*G25*6 -> 0 | I25: =VLOOKUP(C25,'NHẬP KHO '!C:U,18,0) -> 0 | J25: =VLOOKUP(C25,'XUẤT KHO'!C:Z,23,0) -> 0 | K25: =G25+I25-J25 -> 0 | L25: =F25*K25*6 -> 0
A26: 21 | B26: Thanh ghép 2mm | C26: C3300 | E26: Xám sần | F26: 0.364 | G26: 6 | H26: =F26*G26*6 -> 13.104 | I26: =VLOOKUP(C26,'NHẬP KHO '!C:U,18,0) -> 19 | J26: =VLOOKUP(C26,'XUẤT KHO'!C:Z,23,0) -> 1 | K26: =G26+I26-J26 -> 24 | L26: =F26*K26*6 -> 52.416
A27: 22 | B27: Pano | C27: F077 | E27: Xám sần | F27: 0.697 | H27: =F27*G27*6 -> 0 | I27: =VLOOKUP(C27,'NHẬP KHO '!C:U,18,0) -> 0 | J27: =VLOOKUP(C27,'XUẤT KHO'!C:Z,23,0) -> 0 | K27: =G27+I27-J27 -> 0 | L27: =F27*K27*6 -> 0
A28: 23 | B28: Ngưỡng cửa đi | C28: C3319 | E28: Xám sần | F28: 0.723 | H28: =F28*G28*6 -> 0 | I28: =VLOOKUP(C28,'NHẬP KHO '!C:U,18,0) -> 0 | J28: =VLOOKUP(C28,'XUẤT KHO'!C:Z,23,0) -> 0 | K28: =G28+I28-J28 -> 0 | L28: =F28*K28*6 -> 0
A29: 24 | B29: Khung chớp | C29: E1283 | E29: Xám sần | F29: 0.21 | G29: 7 | H29: =F29*G29*6 -> 8.82 | I29: =VLOOKUP(C29,'NHẬP KHO '!C:U,18,0) -> 0 | J29: =VLOOKUP(C29,'XUẤT KHO'!C:Z,23,0) -> 3 | K29: =G29+I29-J29 -> 4 | L29: =F29*K29*6 -> 5.04
A30: 25 | B30: Nan chớp | C30: E192 | E30: Xám sần | F30: 0.34 | G30: 3 | H30: =F30*G30*6 -> 6.12 | I30: =VLOOKUP(C30,'NHẬP KHO '!C:U,18,0) -> 0 | J30: =VLOOKUP(C30,'XUẤT KHO'!C:Z,23,0) -> 0 | K30: =G30+I30-J30 -> 3 | L30: =F30*K30*6 -> 6.12
A31: 26 | B31: Cánh cửa đi mở trong mới | C31: VRA55-02 | E31: Xám sần | F31: 1.515 | G31: 14 | H31: =F31*G31*6 -> 127.26 | I31: =VLOOKUP(C31,'NHẬP KHO '!C:U,18,0) -> 0 | J31: =VLOOKUP(C31,'XUẤT KHO'!C:Z,23,0) -> 0 | K31: =G31+I31-J31 -> 14 | L31: =F31*K31*6 -> 127.26 | N31: 2 cây cũ
A32: 27 | B32: Cánh cửa đi mở ngoài mới | C32: VRA55-03 | E32: Xám sần | F32: 1.515 | G32: 22 | H32: =F32*G32*6 -> 199.98 | I32: =VLOOKUP(C32,'NHẬP KHO '!C:U,18,0) -> 0 | J32: =VLOOKUP(C32,'XUẤT KHO'!C:Z,23,0) -> 4 | K32: =G32+I32-J32 -> 18 | L32: =F32*K32*6 -> 163.62 | N32: 4 cây cũ
A33: 28 | B33: Cánh cửa sổ mới | C33: VRA55-01 | E33: Xám sần | F33: 1.163 | G33: 10 | H33: =F33*G33*6 -> 69.78 | I33: =VLOOKUP(C33,'NHẬP KHO '!C:U,18,0) -> 0 | J33: =VLOOKUP(C33,'XUẤT KHO'!C:Z,23,0) -> 3 | K33: =G33+I33-J33 -> 7 | L33: =F33*K33*6 -> 48.846
A34: 29 | B34: Nẹp kính hộp cho VRA55 cánh cửa sổ mới | C34: VRA55-04 | E34: Xám sần | F34: 0.233 | G34: 40 | H34: =F34*G34*6 -> 55.92 | I34: =VLOOKUP(C34,'NHẬP KHO '!C:U,18,0) -> 0 | J34: =VLOOKUP(C34,'XUẤT KHO'!C:Z,23,0) -> 0 | K34: =G34+I34-J34 -> 40 | L34: =F34*K34*6 -> 55.92
A35: 30 | B35: Ốp chân cánh cửa đi | C35: C22900 | E35: Xám sần | F35: 0.405 | G35: 25 | H35: =F35*G35*6 -> 60.75 | I35: =VLOOKUP(C35,'NHẬP KHO '!C:U,18,0) -> 0 | J35: =VLOOKUP(C35,'XUẤT KHO'!C:Z,23,0) -> 0 | K35: =G35+I35-J35 -> 25 | L35: =F35*K35*6 -> 60.75
A36: 31 | B36: Sập kính hộp | C36: SH6002 | E36: Xám sần | F36: 0.31 | G36: 57 | H36: =F36*G36*6 -> 106.02 | I36: =VLOOKUP(C36,'NHẬP KHO '!C:U,18,0) -> 20 | J36: =VLOOKUP(C36,'XUẤT KHO'!C:Z,23,0) -> 37 | K36: =G36+I36-J36 -> 40 | L36: =F36*K36*6 -> 74.4
A37: 32 | B37: Sập kính hộp | C37: SH6001 | E37: Xám sần | F37: 0.278 | G37: 20 | H37: =F37*G37*6 -> 33.36 | I37: =VLOOKUP(C37,'NHẬP KHO '!C:U,18,0) -> 20 | J37: =VLOOKUP(C37,'XUẤT KHO'!C:Z,23,0) -> 13 | K37: =G37+I37-J37 -> 27 | L37: =F37*K37*6 -> 45.036
A38: II | B38: VRA-Hệ 50 | E38: Xám sần | G38: =SUM(G39:G41) -> 2 | H38: =SUM(H39:H41) -> 11.496 | I38: =SUM(I39:I41) -> 0 | J38: =SUM(J39:J41) -> 0 | K38: =SUM(K39:K41) -> 2 | L38: =SUM(L39:L41) -> 11.496 | N38: =SUM(N39:N41) -> 0 | O38: =SUM(O39:O41) -> 0
A39: 1 | B39: Cánh cửa sổ | C39: VRA50-02 | E39: Xám sần | F39: 0.958 | G39: 2 | H39: =F39*G39*6 -> 11.496 | I39: =VLOOKUP(C39,'NHẬP KHO '!C:U,18,0) -> 0 | J39: =VLOOKUP(C39,'XUẤT KHO'!C:Z,23,0) -> 0 | K39: =G39+I39-J39 -> 2 | L39: =F39*K39*6 -> 11.496
A40: 2 | B40: Cánh cửa đi | C40: VRA50-01 | E40: Xám sần | F40: 1.038 | H40: =F40*G40*6 -> 0 | I40: =VLOOKUP(C40,'NHẬP KHO '!C:U,18,0) -> 0 | J40: =VLOOKUP(C40,'XUẤT KHO'!C:Z,23,0) -> 0 | K40: =G40+I40-J40 -> 0 | L40: =F40*K40*6 -> 0
...

Sheet XUẤT KHO
A2: STT | B2: TÊN GỌI | C2: MÃ CÂY | D2: MẶT CẮT | E2: MÀU SẮC | F2: TỶ TRỌNG THÔ | G2: MD | H2: 20/11 | I2: 19/11 | J2: 27/11 | Y2: TỔNG XUẤT (cây) | Z2: TỔNG XUẤT THEO KG
A3: Nhà CC | F3: A | H3: ĐL Dũng Lâm | I3: Chú Thiện - Nam Định | J3: Xuất nhôm Anh Long - Phú Thọ | K3: Mái Thuận Hường BỔ SUNG | L3: Anh Vũ - Mỹ Đình( dự bị xuất) | Y3: B | Z3: C=A*B*6m
A4: TỔNG CÂY | H4: =SUM(H5:H127) -> 2 | I4: =SUM(I5:I127) -> 165 | J4: =SUM(J5:J127) -> 53 | K4: =SUM(K5:K127) -> 10 | L4: =SUM(L5:L127) -> 0 | M4: =SUM(M5:M127) -> 0 | N4: =SUM(N5:N127) -> 0 | O4: =SUM(O5:O127) -> 0 | ... X4: =SUM(X5:X127) -> 0 | Y4: =Y122+Y111+Y96+Y71+Y62+Y49+Y46+Y42+Y38+Y5 -> 230
A5: I | B5: VRA-Hệ 55 Mở quay | E5: Xám sần | Y5: =SUM(Y6:Y37) -> 85 | Z5: =SUM(Z6:Z37) -> 254.73
A6: 1 | B6: Khung vách | C6: C3209 | E6: Xám sần | F6: 0.842 | G6: 6 | J6: 6 | Y6: =SUM(H6:X6) -> 6 | Z6: =F6*Y6*6 -> 30.312
A7: 2 | B7: Khung bao cửa sổ mở quay | C7: C3318 | E7: Xám sần | F7: 0.887 | G7: 6 | J7: 3 | Y7: =SUM(H7:X7) -> 3 | Z7: =F7*Y7*6 -> 15.966
A8: 3 | B8: Cây đảo khuôn bao | C8: C3208 | E8: Xám sần | F8: 0.798 | G8: 6 | Y8: =SUM(H8:X8) -> 0 | Z8: =F8*Y8*6 -> 0
A9: 4 | B9: Cánh cửa sổ mở ngoài | C9: C3202P | E9: Xám sần | F9: 1.127 | G9: 6 | Y9: =SUM(H9:X9) -> 0 | Z9: =F9*Y9*6 -> 0
A10: 5 | B10: Đố tĩnh chia Khung cửa sổ | C10: C3313 | E10: Xám sần | F10: 1.056 | G10: 6 | Y10: =SUM(H10:X10) -> 0 | Z10: =F10*Y10*6 -> 0
A11: 6 | B11: Đố tĩnh chia cánh | C11: C3203 | E11: Xám sần | F11: 1.001 | G11: 6 | I11: 1 | Y11: =SUM(H11:X11) -> 1 | Z11: =F11*Y11*6 -> 6.006
A12: 7 | B12: Khung bao cửa đi | C12: C3328 | E12: Xám sần | F12: 1.286 | G12: 6 | J12: 4 | Y12: =SUM(H12:X12) -> 4 | Z12: =F12*Y12*6 -> 30.864
A13: 8 | B13: Cánh cửa đi mở ngoài | C13: C3303P | E13: Xám sần | F13: 1.496 | G13: 6 | Y13: =SUM(H13:X13) -> 0 | Z13: =F13*Y13*6 -> 0
A14: 9 | B14: Cánh cửa đi mở trong | C14: C3332P | E14: Xám sần | F14: 1.496 | G14: 6 | Y14: =SUM(H14:X14) -> 0 | Z14: =F14*Y14*6 -> 0
A15: 10 | B15: Đố ngang dưới cánh cửa đi | C15: C3304P | E15: Xám sần | F15: 2.107 | G15: 6 | Y15: =SUM(H15:X15) -> 0 | Z15: =F15*Y15*6 -> 0
A16: 11 | B16: Đố động cửa đi | C16: C3323 | E16: Xám sần | F16: 0.828 | G16: 6 | J16: 1 | Y16: =SUM(H16:X16) -> 1 | Z16: =F16*Y16*6 -> 4.968
A17: 12 | B17: Ốp chân cánh cửa đi | C17: C3329 | E17: Xám sần | F17: 0.448 | G17: 6 | Y17: =SUM(H17:X17) -> 0 | Z17: =F17*Y17*6 -> 0
A18: 13 | B18: Nẹp kính đơn >12mm | C18: C3295 | E18: Xám sần | F18: 0.238 | G18: 6 | J18: 8 | Y18: =SUM(H18:X18) -> 8 | Z18: =F18*Y18*6 -> 11.424
A19: 14 | B19: Nẹp kính khung bao | C19: C3296 | E19: Xám sần | F19: 0.246 | G19: 6 | Y19: =SUM(H19:X19) -> 0 | Z19: =F19*Y19*6 -> 0
A20: 15 | B20: Nẹp kính hộp >22mm | C20: C3236 | E20: Xám sần | F20: 0.238 | G20: 6 | I20: 1 | Y20: =SUM(H20:X20) -> 1 | Z20: =F20*Y20*6 -> 1.428
A21: 16 | B21: Nẹp kính hộp >25mm | C21: C3286 | E21: Xám sần | F21: 0.238 | G21: 6 | Y21: =SUM(H21:X21) -> 0 | Z21: =F21*Y21*6 -> 0
A22: 17 | B22: Sập kính hộp cho khung > 21mm | C22: C3225 | E22: Xám sần | F22: 0.233 | G22: 6 | Y22: =SUM(H22:X22) -> 0 | Z22: =F22*Y22*6 -> 0
A23: 18 | B23: Thanh chuyển góc 90 độ | C23: C3326 | E23: Xám sần | F23: 0.933 | G23: 6 | Y23: =SUM(H23:X23) -> 0 | Z23: =F23*Y23*6 -> 0
A24: 19 | B24: Thanh tăng cứng vách và cửa | C24: C3310 | E24: Xám sần | F24: 1.371 | G24: 6 | Y24: =SUM(H24:X24) -> 0 | Z24: =F24*Y24*6 -> 0
A25: 20 | B25: Cây chuyển góc 135 độ | C25: C910 | E25: Xám sần | F25: 0.962 | G25: 6 | Y25: =SUM(H25:X25) -> 0 | Z25: =F25*Y25*6 -> 0
A26: 21 | B26: Thanh ghép 2mm | C26: C3300 | E26: Xám sần | F26: 0.364 | G26: 6 | J26: 1 | Y26: =SUM(H26:X26) -> 1 | Z26: =F26*Y26*6 -> 2.184
A27: 22 | B27: Pano | C27: F077 | E27: Xám sần | F27: 0.697 | G27: 6 | Y27: =SUM(H27:X27) -> 0 | Z27: =F27*Y27*6 -> 0
A28: 23 | B28: Ngưỡng cửa đi | C28: C3319 | E28: Xám sần | F28: 0.723 | G28: 6 | Y28: =SUM(H28:X28) -> 0 | Z28: =F28*Y28*6 -> 0
A29: 24 | B29: Khung chớp | C29: E1283 | E29: Xám sần | F29: 0.21 | G29: 6 | K29: 3 | Y29: =SUM(H29:X29) -> 3 | Z29: =F29*Y29*6 -> 3.78
A30: 25 | B30: Nan chớp | C30: E192 | E30: Xám sần | F30: 0.34 | G30: 6 | Y30: =SUM(H30:X30) -> 0 | Z30: =F30*Y30*6 -> 0
A31: 26 | B31: Cánh cửa đi mở trong mới | C31: VRA55-02 | E31: Xám sần | F31: 1.515 | G31: 6 | Y31: =SUM(H31:X31) -> 0 | Z31: =F31*Y31*6 -> 0
A32: 27 | B32: Cánh cửa đi mở ngoài mới | C32: VRA55-03 | E32: Xám sần | F32: 1.515 | G32: 6 | J32: 4 | Y32: =SUM(H32:X32) -> 4 | Z32: =F32*Y32*6 -> 36.36
A33: 28 | B33: Cánh cửa sổ mới | C33: VRA55-01 | E33: Xám sần | F33: 1.163 | G33: 6 | J33: 3 | Y33: =SUM(H33:X33) -> 3 | Z33: =F33*Y33*6 -> 20.934
A34: 29 | B34: Nẹp kính hộp cho VRA55 cánh cửa sổ mới | C34: VRA55-04 | E34: Xám sần | F34: 0.233 | G34: 6 | Y34: =SUM(H34:X34) -> 0 | Z34: =F34*Y34*6 -> 0
B35: Ốp chân cánh cửa đi | C35: C22900 | E35: Xám sần | F35: 0.405 | G35: 6 | Y35: =SUM(H35:X35) -> 0 | Z35: =F35*Y35*6 -> 0
A36: 30 | B36: Sập kính hộp | C36: SH6002 | E36: Xám sần | F36: 0.31 | G36: 6 | H36: 1 | I36: 29 | J36: 7 | Y36: =SUM(H36:X36) -> 37 | Z36: =F36*Y36*6 -> 68.82
A37: 31 | B37: Sập kính hộp | C37: SH6001 | E37: Xám sần | F37: 0.278 | G37: 6 | I37: 13 | Y37: =SUM(H37:X37) -> 13 | Z37: =F37*Y37*6 -> 21.684
A38: II | B38: VRA-Hệ 50 | E38: Xám sần | Y38: =Y39+Y40+Y41 -> 0 | Z38: =Z39+Z40+Z41 -> 0
A39: 1 | B39: Cánh cửa sổ | C39: VRA50-02 | E39: Xám sần | F39: 0.958 | G39: 6 | Y39: =SUM(H39:X39) -> 0 | Z39: =F39*Y39*6 -> 0
A40: 2 | B40: Cánh cửa đi | C40: VRA50-01 | E40: Xám sần | F40: 1.038 | G40: 6 | Y40: =SUM(H40:X40) -> 0 | Z40: =F40*Y40*6 -> 0
A41: 3 | B41: Chia ô nhỏ | C41: Q56A | E41: Xám sần | F41: 0.75 | G41: 6 | Y41: =SUM(H41:X41) -> 0 | Z41: =F41*Y41*6 -> 0
...

Sheet NHẬP KHO 
A2: STT | B2: TÊN GỌI | C2: MÃ CÂY | D2: MẶT CẮT | E2: MÀU SẮC | F2: TỶ TRỌNG THÔ | G2: 18/11 | H2: 24/11 | I2: 25/11 | T2: TỔNG NHẬP (cây) | U2: TỔNG NHẬP THEO KG
A3: Nhà CC | G3: ĐÔNG ÂU | H3: ĐÔNG ÂU | I3: Yangly | T3: B | U3: C=A*B*6m
A4: TỔNG SỐ CÂY NHẬP | G4: =SUM(G6:G127) -> 194 | H4: =SUM(H6:H127) -> 110 | I4: =SUM(I6:I127) -> 94 | J4: =SUM(J6:J127) -> 0 | K4: =SUM(K6:K127) -> 0 | L4: =SUM(L6:L127) -> 0 | M4: =SUM(M6:M127) -> 0 | N4: =SUM(N6:N127) -> 0 | ... S4: =SUM(S6:S127) -> 0 | T4: =T5+T38+T42+T49+T62+T71+T96+T111+T122 -> 398
A5: I | B5: VRA-Hệ 55 Mở quay | E5: Xám sần | T5: =SUM(T6:T37) -> 85 | U5: =SUM(U6:U37) -> 243.408
A6: 1 | B6: Khung vách | C6: C3209 | E6: Xám sần | F6: 0.842 | H6: 26 | T6: =SUM(G6:S6) -> 26 | U6: =F6*T6*6 -> 131.352
A7: 2 | B7: Khung bao cửa sổ mở quay | C7: C3318 | E7: Xám sần | F7: 0.887 | T7: =SUM(G7:S7) -> 0 | U7: =F7*T7*6 -> 0
A8: 3 | B8: Cây đảo khuôn bao | C8: C3208 | E8: Xám sần | F8: 0.798 | T8: =SUM(G8:S8) -> 0 | U8: =F8*T8*6 -> 0
A9: 4 | B9: Cánh cửa sổ mở ngoài | C9: C3202P | E9: Xám sần | F9: 1.127 | T9: =SUM(G9:S9) -> 0 | U9: =F9*T9*6 -> 0
A10: 5 | B10: Đố tĩnh chia Khung cửa sổ | C10: C3313 | E10: Xám sần | F10: 1.056 | T10: =SUM(G10:S10) -> 0 | U10: =F10*T10*6 -> 0
A11: 6 | B11: Đố tĩnh chia cánh | C11: C3203 | E11: Xám sần | F11: 1.001 | T11: =SUM(G11:S11) -> 0 | U11: =F11*T11*6 -> 0
A12: 7 | B12: Khung bao cửa đi | C12: C3328 | E12: Xám sần | F12: 1.286 | T12: =SUM(G12:S12) -> 0 | U12: =F12*T12*6 -> 0
A13: 8 | B13: Cánh cửa đi mở ngoài | C13: C3303P | E13: Xám sần | F13: 1.496 | T13: =SUM(G13:S13) -> 0 | U13: =F13*T13*6 -> 0
A14: 9 | B14: Cánh cửa đi mở trong | C14: C3332P | E14: Xám sần | F14: 1.496 | T14: =SUM(G14:S14) -> 0 | U14: =F14*T14*6 -> 0
A15: 10 | B15: Đố ngang dưới cánh cửa đi | C15: C3304P | E15: Xám sần | F15: 2.107 | T15: =SUM(G15:S15) -> 0 | U15: =F15*T15*6 -> 0
A16: 11 | B16: Đố động cửa đi | C16: C3323 | E16: Xám sần | F16: 0.828 | T16: =SUM(G16:S16) -> 0 | U16: =F16*T16*6 -> 0
A17: 12 | B17: Ốp chân cánh cửa đi | C17: C3329 | E17: Xám sần | F17: 0.448 | T17: =SUM(G17:S17) -> 0 | U17: =F17*T17*6 -> 0
A18: 13 | B18: Nẹp kính đơn >12mm | C18: C3295 | E18: Xám sần | F18: 0.238 | T18: =SUM(G18:S18) -> 0 | U18: =F18*T18*6 -> 0
... A25: 20 | B25: Cây chuyển góc 135 độ | C25: C910 | E25: Xám sần | F25: 0.962 | T25: =SUM(G25:S25) -> 0 | U25: =F25*T25*6 -> 0
A26: 21 | B26: Thanh ghép 2mm | C26: C3300 | E26: Xám sần | F26: 0.364 | I26: 19 | T26: =SUM(G26:S26) -> 19 | U26: =F26*T26*6 -> 41.496
A27: 22 | B27: Pano | C27: F077 | E27: Xám sần | F27: 0.697 | T27: =SUM(G27:S27) -> 0 | U27: =F27*T27*6 -> 0
A28: 23 | B28: Ngưỡng cửa đi | C28: C3319 | E28: Xám sần | F28: 0.723 | T28: =SUM(G28:S28) -> 0 | U28: =F28*T28*6 -> 0
A29: 24 | B29: Khung chớp | C29: E1283 | E29: Xám sần | F29: 0.21 | T29: =SUM(G29:S29) -> 0 | U29: =F29*T29*6 -> 0
A30: 25 | B30: Nan chớp | C30: E192 | E30: Xám sần | F30: 0.34 | T30: =SUM(G30:S30) -> 0 | U30: =F30*T30*6 -> 0
A31: 26 | B31: Cánh cửa đi mở trong mới | C31: VRA55-02 | E31: Xám sần | F31: 1.515 | T31: =SUM(G31:S31) -> 0 | U31: =F31*T31*6 -> 0
A32: 27 | B32: Cánh cửa đi mở ngoài mới | C32: VRA55-03 | E32: Xám sần | F32: 1.515 | T32: =SUM(G32:S32) -> 0 | U32: =F32*T32*6 -> 0
A33: 28 | B33: Cánh cửa sổ mới | C33: VRA55-01 | E33: Xám sần | F33: 1.163 | T33: =SUM(G33:S33) -> 0 | U33: =F33*T33*6 -> 0
A34: 29 | B34: Nẹp kính hộp cho VRA55 cánh cửa sổ mới | C34: VRA55-04 | E34: Xám sần | F34: 0.233 | T34: =SUM(G34:S34) -> 0 | U34: =F34*T34*6 -> 0
A35: 30 | B35: Ốp chân cánh cửa đi | C35: C22900 | E35: Xám sần | F35: 0.405 | T35: =SUM(G35:S35) -> 0 | U35: =F35*T35*6 -> 0
A36: 31 | B36: Sập kính hộp | C36: SH6002 | E36: Xám sần | F36: 0.31 | G36: 20 | T36: =SUM(G36:S36) -> 20 | U36: =F36*T36*6 -> 37.2
A37: 32 | B37: Sập kính hộp | C37: SH6001 | E37: Xám sần | F37: 0.278 | G37: 20 | T37: =SUM(G37:S37) -> 20 | U37: =F37*T37*6 -> 33.36
A38: II | B38: VRA-Hệ 50 | E38: Xám sần | T38: =SUM(T39:T41) -> 0 | U38: =SUM(U39:U41) -> 0
A39: 1 | B39: Cánh cửa sổ | C39: VRA50-02 | E39: Xám sần | F39: 0.958 | T39: =SUM(G39:S39) -> 0 | U39: =F39*T39*6 -> 0
A40: 2 | B40: Cánh cửa đi | C40: VRA50-01 | E40: Xám sần | F40: 1.038 | T40: =SUM(G40:S40) -> 0 | U40: =F40*T40*6 -> 0
A41: 3 | B41: Chia ô nhỏ | C41: Q56A | E41: Xám sần | F41: 0.75 | T41: =SUM(G41:S41) -> 0 | U41: =F41*T41*6 -> 0
A42: III | B42: VRA-Hệ 64 Cửa sổ lùa | E42: Xám sần | T42: =SUM(T43:T45) -> 0 | U42: =SUM(U43:U45) -> 0
A43: 1 | B43: Khung cửa lùa | C43: VRA64-01 | E43: Xám sần | F43: 1.041 | T43: =SUM(G43:S43) -> 0 | U43: =F43*T43*6 -> 0
A44: 2 | B44: Cánh cửa lùa | C44: VRA64-02 | E44: Xám sần | F44: 1.155 | T44: =SUM(G44:S44) -> 0 | U44: =F44*T44*6 -> 0
A45: 3 | B45: Ốp móc cửa lùa | C45: VRA64-03 | E45: Xám sần | F45: 0.42 | T45: =SUM(G45:S45) -> 0 | U45: =F45*T45*6 -> 0
A46: V | B46: VRE -Hệ 65 Mở quay | C46: Mạnh Quy | E46: Xám sần | T46: =SUM(T47:T48) -> 0 | U46: =SUM(U47:U48) -> 0
A47: 10 | B47: Che chân | C47: ALUK-EU C6517 | E47: Xám sần | F47: 0.239 | T47: =SUM(G47:S47) -> 0 | U47: =F47*T47*6 -> 0
...
